[TOC]



# 第12章 异常处理

1. 原因：由于环境条件和用户操作的正确性是没有百分之百的保障的，所以在设计程序时，就要充分考虑到各种意外情况，并给予恰当的处理。这就是异常处理。



## 12.1 异常处理的基本思想

1. 任务：程序运行中的有些错误是可以预料但不可避免的，这时要力争做到允许用户排除环境错误，继续运行程序；至少要给出恰当的提示信息。
2. 基本思想：C++异常处理机制使得异常的引发和处理不必在同一函数中。这样底层函数可以着重解决具体问题，而不必过多地考虑对异常的处理；上层调用者可以在适当的位置设计对不同类型异常的处理。



## 12.2 C++异常处理的实现

### 12.2.1 异常处理的语法

1. throw表达式语法：

    ```C++
    throw 表达式;
    
    // 将自己不能处理的异常抛出给调用者。
    // 若有多种要抛出的异常，应用不同的操作数类型来相互区别。
    ```

2. try块语法：

    ```C++
    try
        复合语句;		// (代码的保护段，即有可能发生异常的代码段。如果遇到异常，其中的throw会抛掷)
    catch(异常声明)
        复合语句;		// (异常处理程序。捕获由throw抛掷的异常)
    catch(异常声明)
        复合语句;
    
    // 异常声明部分指明了子句处理的异常的类型和异常参数的名称，与函数形参类似，可以是某个类型的值或引用；
    // 类型可以是任何有效的数据类型，可以是C++的类；
    // 当异常被抛掷后，catch子句依次被检查，若某个catch子句的异常类型与被抛掷的异常类型一致，则执行该段异常处理程序；如果异常声明是一个省略号(...)，catch便处理所有类型的异常，通常是try块的最后一段。
    ```

3. NOTE：

    * 异常声明的形式与函数声明的形式类似。函数声明中允许只声明类型，而不给出参数名。catch子句的异常声明中也允许不给出异常参数名称，只是在这种情况下复合语句中就无法访问异常对象了；

4. 异常处理的执行过程：

    * 程序通过正常的顺序执行到try语句，然后执行try块内的保护段；
    * 如果在保护段执行期间没有引起异常，那么跟在try块后的catch子句就不执行。程序从异常被抛掷的try块后跟随的最后一个catch子句后面的语句继续执行下去；
    * 程序执行到一个throw表达式时，一个异常对象会被创建。若异常的抛出点本身在一个try子句内，则该try子句后跟的catch子句会按顺序检查异常类型是否与声明的类型匹配；若异常抛出点本身不在任何try子句内，或抛出的异常与各个catch子句所声明的类型皆不匹配，则结束当前函数的执行，回到当前函数的调用点，把调用点作为异常的抛出点，然后重复这一过程，直到异常成功被一个catch语句捕获；
    * 如果始终未能找到与被抛掷异常匹配的catch子句，最终main函数会结束执行(运行库函数terminate将被自动调用，终止程序)；
    * 如果找到一个匹配的catch子句，则catch子句后的复合语句将会被执行。复合语句执行完毕后，当前的try块即执行完毕；

5. 抛出异常与catch子句异常匹配的条件：

    * catch子句中声明的异常类型就是抛出异常对象的类型或引用；
    * catch子句中声明的异常类型是抛出异常对象的类型的公有基类或其引用；
    * 抛出的异常类型和catch子句中声明的异常类型皆为指针类型，且前者到后者可以隐含转换；

6. 程序实例：处理除0异常

    ```C++
    #include <iostream>
    using namespace std;
    
    int divide(int x, int y)
    {
        if(y == 0)
            throw x;
        return x/y;
    }
    
    int main()
    {
        try
        {
            cout << "5/2 = " << divide(5, 2) << endl;		// 正常执行
            cout << "8/0 = " << divide(8, 0) << endl;		// 抛出异常
            cout << "7/1 = " << divide(7, 1) << endl;		// 不会被执行
        }
        catch(int e)
        {
            cout << e << "is divide by zero!" << endl;
        }
        cout << "That is OK." << endl;
        return 0;
    }
    ```



### 12.2.2 异常接口声明

1. 目的：为了加强程序的可读性，使函数的用户能够方便地知道所使用的函数会抛出哪些异常，可以在这个函数的声明中列出这个函数可能抛掷的所有异常类型；

2. 举例：

    ```C++
    void fun() throw(A, B, C, D);
    // 只能抛掷类型A, B, C, D及其子类型的异常
    
    void fun();
    // 可以抛掷任何类型的异常
    
    void fun() throw();
    // 不抛掷任何类型的异常
    ```

3. Note：

    * 如果一个函数抛出了它的异常接口声明所不允许的异常时，unexpected函数会被调用，该函数的默认行为是调用terminate函数终止程序。用户也可以定义自己的unexpected函数，替换默认的函数。



## 12.3 异常处理中的构造与析构

1. C++异常处理的真正功能：

    * 不仅在于它能够处理各种不同类型的异常；
    * 还在于它具有为异常抛掷前构造的所有局部对象自动调用析构函数的能力；

2. 栈的解旋(unwinding)：

    * 异常被抛出后，从进入try块(与截获异常的catch子句对应的那个try块)起，到异常抛掷前，这期间在栈上构造(且并未析构)的所有对象都会被自动析构，析构的顺序与构造的顺序相反；

3. 程序实例：

    ```C++
    
    #include <iostream>
    #include <string>
    using namespace std;
    
    class MyException
    {
        public:
        	MyException(const string& message): message(message) {}
        	~MyException() {}
        	const string& getMessage() const {return message;}
        
        private:
        	string message;
    };
    
    class Demo
    {
        public:
        	Demo() {cout << "Constructor of Demo" << endl;}
        	~Demo() {cout << "Destructor of Demo" << endl;}
    };
    
    void func() throw(MyException)
    {
        Demo d;
        cout << "Throw MyException in func()" << endl;
        throw MyException("exception thrown by func()");
    }
    
    int main(int argc, char* argv[])
    {
        cout << "In main function" << endl;
        try
        {
            func();
        }
        catch (MyException& e)
        {
            cout << "Caught an exception:" << e.getMessage() << endl;
        }
        cout << "Resume the execution of main()" << endl;
        return 0;
    }
    
    /*
    	Outputs:
    		In main function
    		Constructor of Demo
    		Throw MyException in func()
    		Destructor of Demo
    		Caught an exception: exception thrown by func()
    		Resume the execution of main()
    */
    ```

4. NOTE：

    * 用一个不带操作数的throw表达式可以将当前正在被处理的异常再次抛掷，这样一个表达式只能出现在一个catch子句中或者catch子句内部调用的函数中。

    * 再次抛掷的异常是源异常对象，而不是副本；

    * 示例：

        ```C++
        try
        {
            throw MyException("some exception");
        }
        catch (...)
        {
            throw;
        }
        ```

        



## 12.4 标准程序库异常处理

1. Exception类：

    * C++标准中提供了一组标准异常类，这些类以基类Exception开始；

    * 标准程序库中抛出的所有异常，都派生于该基类；

    * Exception基类提供了一个成员函数what()，用于返回错误信息；

        ```C++
        virtual const char* what() const throw();
        ```

2. C++标准库中各种异常类所代表的异常：

3. 程序实例：

    ```C++
    // 用海伦公式计算三角形面积
    
    #include <iostream>
    #include <cmath>
    #include <stdexcept>
    using namespace std;
    
    double area(double a, double b, double c) throw(invalid_argument)
    {
        if(a <= 0 || b <= 0 || c <= 0)
            throw invalid_argument("the side length should be positive");
        
        if(a + b <= c || b + c <= a || a + c <= b)
            throw invalid_argument("the side length should fit the triangle inequation");
        
        double s = (a + b + c) / 2;
        return sqrt(s * (s - a) * (s - b) * (s - c));
    }
    
    int main(int argc, char* argv[])
    {
        double a, b, c;
        cout << "Please input the side lengths of a triangle: ";
        cin >> a >> b >> c;
        
        try
        {
            double s = area(a, b, c);
            cout << "Area: " << s << endl;
        }
        catch (exception& e)
        {
            cout << "Error: " << e.what() << endl;
        }
        
        return 0;
    }
    ```

    

## 12.5 综合实例：个人银行账户管理程序





## 12.6 深度探索

### 12.6.1 异常安全性问题



### 12.6.2 避免异常发生时的资源泄漏

